
[ERROR] 2025-06-18 17:44:07,449 django.request - Internal Server Error: /accounts/google/login/
Traceback (most recent call last):
  File "/root/.cache/pypoetry/virtualenvs/codebay-final-project-9TtSrW0h-py3.12/lib/python3.12/site-packages/asgiref/sync.py", line 518, in thread_handler
    raise exc_info[1]
  File "/root/.cache/pypoetry/virtualenvs/codebay-final-project-9TtSrW0h-py3.12/lib/python3.12/site-packages/django/core/handlers/exception.py", line 42, in inner
    response = await get_response(request)
               ^^^^^^^^^^^^^^^^^^^^^^^^^^^
  File "/root/.cache/pypoetry/virtualenvs/codebay-final-project-9TtSrW0h-py3.12/lib/python3.12/site-packages/asgiref/sync.py", line 518, in thread_handler
    raise exc_info[1]
  File "/root/.cache/pypoetry/virtualenvs/codebay-final-project-9TtSrW0h-py3.12/lib/python3.12/site-packages/django/core/handlers/base.py", line 253, in _get_response_async
    response = await wrapped_callback(
               ^^^^^^^^^^^^^^^^^^^^^^^
  File "/root/.cache/pypoetry/virtualenvs/codebay-final-project-9TtSrW0h-py3.12/lib/python3.12/site-packages/asgiref/sync.py", line 468, in __call__
    ret = await asyncio.shield(exec_coro)
          ^^^^^^^^^^^^^^^^^^^^^^^^^^^^^^^
  File "/root/.cache/pypoetry/virtualenvs/codebay-final-project-9TtSrW0h-py3.12/lib/python3.12/site-packages/asgiref/current_thread_executor.py", line 40, in run
    result = self.fn(*self.args, **self.kwargs)
             ^^^^^^^^^^^^^^^^^^^^^^^^^^^^^^^^^^
  File "/root/.cache/pypoetry/virtualenvs/codebay-final-project-9TtSrW0h-py3.12/lib/python3.12/site-packages/asgiref/sync.py", line 522, in thread_handler
    return func(*args, **kwargs)
           ^^^^^^^^^^^^^^^^^^^^^
  File "/root/.cache/pypoetry/virtualenvs/codebay-final-project-9TtSrW0h-py3.12/lib/python3.12/site-packages/allauth/socialaccount/providers/oauth2/views.py", line 105, in view
    return self.dispatch(request, *args, **kwargs)
           ^^^^^^^^^^^^^^^^^^^^^^^^^^^^^^^^^^^^^^^
  File "/root/.cache/pypoetry/virtualenvs/codebay-final-project-9TtSrW0h-py3.12/lib/python3.12/site-packages/allauth/socialaccount/providers/base/views.py", line 15, in dispatch
    provider = self.get_provider()
               ^^^^^^^^^^^^^^^^^^^
  File "/root/.cache/pypoetry/virtualenvs/codebay-final-project-9TtSrW0h-py3.12/lib/python3.12/site-packages/allauth/socialaccount/providers/oauth2/views.py", line 114, in get_provider
    return self.adapter.get_provider()
           ^^^^^^^^^^^^^^^^^^^^^^^^^^^
  File "/root/.cache/pypoetry/virtualenvs/codebay-final-project-9TtSrW0h-py3.12/lib/python3.12/site-packages/allauth/socialaccount/providers/oauth2/views.py", line 48, in get_provider
    return get_adapter(self.request).get_provider(
           ^^^^^^^^^^^^^^^^^^^^^^^^^^^^^^^^^^^^^^^
  File "/root/.cache/pypoetry/virtualenvs/codebay-final-project-9TtSrW0h-py3.12/lib/python3.12/site-packages/allauth/socialaccount/adapter.py", line 213, in get_provider
    app = self.get_app(request, provider=provider, client_id=client_id)
          ^^^^^^^^^^^^^^^^^^^^^^^^^^^^^^^^^^^^^^^^^^^^^^^^^^^^^^^^^^^^^
  File "/root/.cache/pypoetry/virtualenvs/codebay-final-project-9TtSrW0h-py3.12/lib/python3.12/site-packages/allauth/socialaccount/adapter.py", line 303, in get_app
    raise SocialApp.DoesNotExist()
allauth.socialaccount.models.SocialApp.DoesNotExist
